2021-06-08 15:10:22 UTC  29/50 peers      6 MiB chain  0 bytes queue  RPC:  0 conn,    0 req/s,    0 µs
2021-06-08 15:10:23 UTC Imported #12594600 0x128a…2eb1 (172 txs, 14.96 Mgas, 7863 ms, 58.36 KiB)
2021-06-08 15:10:55 UTC  30/50 peers      2 MiB chain  321 KiB queue  RPC:  0 conn,    0 req/s,    0 µs
2021-06-08 15:11:25 UTC  32/50 peers      2 MiB chain  455 KiB queue  RPC:  0 conn,    0 req/s,    0 µs
2021-06-08 15:11:55 UTC  30/50 peers      2 MiB chain  201 KiB queue  RPC:  0 conn,    0 req/s,    0 µs
2021-06-08 15:12:27 UTC  30/50 peers      2 MiB chain  0 bytes queue  RPC:  0 conn,    0 req/s,    0 µs
2021-06-08 15:12:36 UTC Imported #12594615 0xd9b6…efd4 (192 txs, 14.98 Mgas, 7173 ms, 55.64 KiB)
2021-06-08 15:12:58 UTC  31/50 peers      2 MiB chain    1 MiB queue  RPC:  0 conn,    0 req/s,    0 µs
2021-06-08 15:13:30 UTC  33/50 peers      3 MiB chain  391 KiB queue  RPC:  0 conn,    0 req/s,    0 µs
2021-06-08 15:14:01 UTC  31/50 peers      3 MiB chain  0 bytes queue  RPC:  0 conn,    0 req/s,    0 µs
2021-06-08 15:14:23 UTC Panic occured, see stderr for details


====================

stack backtrace:
   0: panic_hook::set_with::{{closure}}
   1: std::panicking::rust_panic_with_hook
             at /rustc/2fd73fabe469357a12c2c974c140f67e7cdd76d0//library/std/src/panicking.rs:595
   2: std::panicking::begin_panic_handler::{{closure}}
             at /rustc/2fd73fabe469357a12c2c974c140f67e7cdd76d0//library/std/src/panicking.rs:497
   3: std::sys_common::backtrace::__rust_end_short_backtrace
             at /rustc/2fd73fabe469357a12c2c974c140f67e7cdd76d0//library/std/src/sys_common/backtrace.rs:141
   4: rust_begin_unwind
             at /rustc/2fd73fabe469357a12c2c974c140f67e7cdd76d0//library/std/src/panicking.rs:493
   5: core::panicking::panic_fmt
             at /rustc/2fd73fabe469357a12c2c974c140f67e7cdd76d0//library/core/src/panicking.rs:92
   6: core::option::expect_none_failed
             at /rustc/2fd73fabe469357a12c2c974c140f67e7cdd76d0//library/core/src/option.rs:1300
   7: <ethcore_network_devp2p::host::Host as ethcore_io::IoHandler<ethcore_network::NetworkIoMessage>>::update_stream
   8: mio::deprecated::event_loop::EventLoop<H>::run
   9: std::sys_common::backtrace::__rust_begin_short_backtrace
  10: core::ops::function::FnOnce::call_once{{vtable.shim}}
  11: <alloc::boxed::Box<F,A> as core::ops::function::FnOnce<Args>>::call_once
             at /rustc/2fd73fabe469357a12c2c974c140f67e7cdd76d0/library/alloc/src/boxed.rs:1521
      <alloc::boxed::Box<F,A> as core::ops::function::FnOnce<Args>>::call_once
             at /rustc/2fd73fabe469357a12c2c974c140f67e7cdd76d0/library/alloc/src/boxed.rs:1521
      std::sys::unix::thread::Thread::new::thread_start
             at /rustc/2fd73fabe469357a12c2c974c140f67e7cdd76d0//library/std/src/sys/unix/thread.rs:71
  12: start_thread
  13: __clone


Thread '<unnamed>' panicked at 'Error reregistering UDP socket: Os { code: 12, kind: Other, message: "Cannot allocate memory" }', crates/net/network-devp2p/src/host.rs:1425

This is a bug. Please report it at:

    https://github.com/openethereum/openethereum/issues/new


2021-06-08 15:14:23 UTC Finishing work, please wait...
2021-06-08 15:14:28 UTC Error on IO service shutdown: NotifyError::Closed(..)
Error: 1