2021-06-08 14:38:59 UTC Imported #12594467 0x58c1…431c (194 txs, 14.81 Mgas, 2684 ms, 74.06 KiB)
2021-06-08 14:39:00 UTC  43/50 peers      4 MiB chain  0 bytes queue  RPC:  0 conn,    0 req/s,    0 µs
2021-06-08 14:39:06 UTC Reorg to #12594468 0x8227…335b (0xb5d0…a5cd #12594466 0x025d…1124 0x58c1…431c)
2021-06-08 14:39:06 UTC Imported #12594468 0x8227…335b (166 txs, 14.98 Mgas, 4663 ms, 58.98 KiB)
2021-06-08 14:39:30 UTC  43/50 peers      4 MiB chain  0 bytes queue  RPC:  0 conn,    0 req/s,    0 µs
2021-06-08 14:39:36 UTC Imported #12594469 0xfba3…e997 (234 txs, 14.99 Mgas, 5355 ms, 75.27 KiB)
2021-06-08 14:39:57 UTC Imported #12594471 0x5276…7209 (185 txs, 14.98 Mgas, 6892 ms, 40.98 KiB)
2021-06-08 14:40:07 UTC  44/50 peers      4 MiB chain  139 KiB queue  RPC:  0 conn,    0 req/s,    0 µs
2021-06-08 14:40:23 UTC Imported #12594474 0xad76…a602 (429 txs, 14.99 Mgas, 5048 ms, 66.28 KiB)
2021-06-08 14:40:37 UTC Imported #12594475 0xda02…5446 (209 txs, 14.99 Mgas, 6520 ms, 57.00 KiB)
2021-06-08 14:40:46 UTC  46/50 peers      4 MiB chain  0 bytes queue  RPC:  0 conn,    0 req/s,    0 µs
2021-06-08 14:40:52 UTC Panic occured, see stderr for details


====================

stack backtrace:
   0: panic_hook::set_with::{{closure}}
   1: std::panicking::rust_panic_with_hook
             at /rustc/2fd73fabe469357a12c2c974c140f67e7cdd76d0//library/std/src/panicking.rs:595
   2: std::panicking::begin_panic_handler::{{closure}}
             at /rustc/2fd73fabe469357a12c2c974c140f67e7cdd76d0//library/std/src/panicking.rs:497
   3: std::sys_common::backtrace::__rust_end_short_backtrace
             at /rustc/2fd73fabe469357a12c2c974c140f67e7cdd76d0//library/std/src/sys_common/backtrace.rs:141
   4: rust_begin_unwind
             at /rustc/2fd73fabe469357a12c2c974c140f67e7cdd76d0//library/std/src/panicking.rs:493
   5: core::panicking::panic_fmt
             at /rustc/2fd73fabe469357a12c2c974c140f67e7cdd76d0//library/core/src/panicking.rs:92
   6: core::option::expect_none_failed
             at /rustc/2fd73fabe469357a12c2c974c140f67e7cdd76d0//library/core/src/option.rs:1300
   7: <ethcore_network_devp2p::host::Host as ethcore_io::IoHandler<ethcore_network::NetworkIoMessage>>::update_stream
   8: mio::deprecated::event_loop::EventLoop<H>::run
   9: std::sys_common::backtrace::__rust_begin_short_backtrace
  10: core::ops::function::FnOnce::call_once{{vtable.shim}}
  11: <alloc::boxed::Box<F,A> as core::ops::function::FnOnce<Args>>::call_once
             at /rustc/2fd73fabe469357a12c2c974c140f67e7cdd76d0/library/alloc/src/boxed.rs:1521
      <alloc::boxed::Box<F,A> as core::ops::function::FnOnce<Args>>::call_once
             at /rustc/2fd73fabe469357a12c2c974c140f67e7cdd76d0/library/alloc/src/boxed.rs:1521
      std::sys::unix::thread::Thread::new::thread_start
             at /rustc/2fd73fabe469357a12c2c974c140f67e7cdd76d0//library/std/src/sys/unix/thread.rs:71
  12: start_thread
  13: __clone


Thread '<unnamed>' panicked at 'Error reregistering UDP socket: Os { code: 22, kind: InvalidInput, message: "Invalid argument" }', crates/net/network-devp2p/src/host.rs:1425

This is a bug. Please report it at:

    https://github.com/openethereum/openethereum/issues/new


2021-06-08 14:40:52 UTC Finishing work, please wait...
2021-06-08 14:40:59 UTC Error on IO service shutdown: NotifyError::Closed(..)
Error: 1