2021-06-08 14:27:59 UTC Imported #12594425 0xdb6b…a2b2 (200 txs, 14.98 Mgas, 6392 ms, 68.04 KiB)
2021-06-08 14:28:01 UTC  34/50 peers      3 MiB chain  0 bytes queue  RPC:  0 conn,    0 req/s,    0 µs
2021-06-08 14:28:16 UTC Imported #12594427 0xbcd6…b5e9 (182 txs, 14.99 Mgas, 4909 ms, 44.14 KiB)
2021-06-08 14:28:26 UTC Imported #12594428 0x18f9…f66b (158 txs, 15.00 Mgas, 5227 ms, 59.53 KiB)
2021-06-08 14:28:36 UTC  33/50 peers      3 MiB chain  0 bytes queue  RPC:  0 conn,    0 req/s,    0 µs
2021-06-08 14:28:44 UTC Imported #12594429 0xe2db…1dc3 (177 txs, 14.98 Mgas, 4855 ms, 60.80 KiB)
2021-06-08 14:29:06 UTC  34/50 peers      4 MiB chain  0 bytes queue  RPC:  0 conn,    0 req/s,    0 µs
2021-06-08 14:29:19 UTC Imported #12594430 0x33d5…c674 (214 txs, 15.00 Mgas, 4353 ms, 49.62 KiB)
2021-06-08 14:29:26 UTC Imported #12594431 0xed6e…b762 (157 txs, 14.98 Mgas, 5698 ms, 45.53 KiB)
2021-06-08 14:29:37 UTC  34/50 peers      4 MiB chain  0 bytes queue  RPC:  0 conn,    0 req/s,    0 µs
2021-06-08 14:29:46 UTC Panic occured, see stderr for details


====================

stack backtrace:
   0: panic_hook::set_with::{{closure}}
   1: std::panicking::rust_panic_with_hook
             at /rustc/2fd73fabe469357a12c2c974c140f67e7cdd76d0//library/std/src/panicking.rs:595
   2: std::panicking::begin_panic_handler::{{closure}}
             at /rustc/2fd73fabe469357a12c2c974c140f67e7cdd76d0//library/std/src/panicking.rs:497
   3: std::sys_common::backtrace::__rust_end_short_backtrace
             at /rustc/2fd73fabe469357a12c2c974c140f67e7cdd76d0//library/std/src/sys_common/backtrace.rs:141
   4: rust_begin_unwind
             at /rustc/2fd73fabe469357a12c2c974c140f67e7cdd76d0//library/std/src/panicking.rs:493
   5: core::panicking::panic_fmt
             at /rustc/2fd73fabe469357a12c2c974c140f67e7cdd76d0//library/core/src/panicking.rs:92
   6: core::option::expect_none_failed
             at /rustc/2fd73fabe469357a12c2c974c140f67e7cdd76d0//library/core/src/option.rs:1300
   7: <ethcore_network_devp2p::host::Host as ethcore_io::IoHandler<ethcore_network::NetworkIoMessage>>::update_stream
   8: mio::deprecated::event_loop::EventLoop<H>::run
   9: std::sys_common::backtrace::__rust_begin_short_backtrace
  10: core::ops::function::FnOnce::call_once{{vtable.shim}}
  11: <alloc::boxed::Box<F,A> as core::ops::function::FnOnce<Args>>::call_once
             at /rustc/2fd73fabe469357a12c2c974c140f67e7cdd76d0/library/alloc/src/boxed.rs:1521
      <alloc::boxed::Box<F,A> as core::ops::function::FnOnce<Args>>::call_once
             at /rustc/2fd73fabe469357a12c2c974c140f67e7cdd76d0/library/alloc/src/boxed.rs:1521
      std::sys::unix::thread::Thread::new::thread_start
             at /rustc/2fd73fabe469357a12c2c974c140f67e7cdd76d0//library/std/src/sys/unix/thread.rs:71
  12: start_thread
  13: __clone


Thread '<unnamed>' panicked at 'Error reregistering UDP socket: Os { code: 17, kind: AlreadyExists, message: "File exists" }', crates/net/network-devp2p/src/host.rs:1425

This is a bug. Please report it at:

    https://github.com/openethereum/openethereum/issues/new


2021-06-08 14:29:46 UTC Finishing work, please wait...
Error: 1