2021-09-22 02:27:57 UTC  Ancient:#5650096 AB:#5650096    1/25 peers    714 KiB chain  0 bytes queue  RPC:  0 conn,    0 req/s,    0 µs
2021-09-22 02:28:33 UTC  Ancient:#5650096 AB:#5650096    1/25 peers    714 KiB chain  0 bytes queue  RPC:  0 conn,    0 req/s,    0 µs
2021-09-22 02:28:33 UTC  Ancient:#5650096 AB:#5650096    1/25 peers    714 KiB chain  0 bytes queue  RPC:  0 conn,    0 req/s,    0 µs
2021-09-22 02:29:23 UTC  Ancient:#5650096 AB:#5650096    1/25 peers    714 KiB chain  0 bytes queue  RPC:  0 conn,    0 req/s,    0 µs
2021-09-22 02:29:54 UTC  Ancient:#5650096 AB:#5650096    1/25 peers    714 KiB chain  0 bytes queue  RPC:  0 conn,    0 req/s,    0 µs
2021-09-22 02:30:24 UTC  Ancient:#5650096 AB:#5650096    0/25 peers    714 KiB chain  0 bytes queue  RPC:  0 conn,    0 req/s,    0 µs
2021-09-22 02:30:54 UTC  Ancient:#5650096 AB:#5650096    0/25 peers    714 KiB chain  0 bytes queue  RPC:  0 conn,    0 req/s,    0 µs
2021-09-22 02:31:29 UTC  Ancient:#5650096 AB:#5650096    0/25 peers    714 KiB chain  0 bytes queue  RPC:  0 conn,    0 req/s,    0 µs
2021-09-22 02:31:59 UTC  Ancient:#5650096 AB:#5650096    0/25 peers    714 KiB chain  0 bytes queue  RPC:  0 conn,    0 req/s,    0 µs
2021-09-22 02:32:20 UTC Syncing #13272861 0x9d94…8f74     0.00 blk/s    0.0 tx/s    0.0 Mgas/s      0+   39 Qed Ancient:#5650096 LI:#13272901    3/25 peers    714 KiB chain   11 MiB queue  RPC:  0 conn,    0 req/s,    0 µs
2021-09-22 02:32:24 UTC Syncing #13272861 0x9d94…8f74     0.00 blk/s    0.0 tx/s    0.0 Mgas/s      0+   40 Qed Ancient:#5650096 LI:#13272902    8/25 peers    949 KiB chain   11 MiB queue  RPC:  0 conn,    0 req/s,    0 µs
2021-09-22 02:32:26 UTC Panic occured, see stderr for details


====================

   0: panic_hook::set_with::{{closure}}
   1: std::panicking::rust_panic_with_hook
             at /rustc/2fd73fabe469357a12c2c974c140f67e7cdd76d0/library/std/src/panicking.rs:595:17
   2: std::panicking::begin_panic_handler::{{closure}}
             at /rustc/2fd73fabe469357a12c2c974c140f67e7cdd76d0/library/std/src/panicking.rs:497:13
   3: std::sys_common::backtrace::__rust_end_short_backtrace
             at /rustc/2fd73fabe469357a12c2c974c140f67e7cdd76d0/library/std/src/sys_common/backtrace.rs:141:18
   4: rust_begin_unwind
             at /rustc/2fd73fabe469357a12c2c974c140f67e7cdd76d0/library/std/src/panicking.rs:493:5
   5: std::panicking::begin_panic_fmt
             at /rustc/2fd73fabe469357a12c2c974c140f67e7cdd76d0/library/std/src/panicking.rs:435:5
   6: ethcore_db::db::Readable::exists_with_cache
   7: <ethcore::client::client::Client as ethcore::client::traits::BlockChainClient>::block_status
   8: ethcore_sync::chain::handler::SyncHandler::on_packet
   9: ethcore_sync::chain::supplier::SyncSupplier::dispatch_packet
  10: <ethcore_sync::api::SyncProtocolHandler as ethcore_network::NetworkProtocolHandler>::read
  11: <ethcore_network_devp2p::host::Host as ethcore_io::IoHandler<ethcore_network::NetworkIoMessage>>::stream_readable
  12: ethcore_io::worker::Worker::new::{{closure}}::{{closure}}
  13: <futures::future::loop_fn::LoopFn<A,F> as futures::future::Future>::poll
  14: std::sys_common::backtrace::__rust_begin_short_backtrace
  15: core::ops::function::FnOnce::call_once{{vtable.shim}}
  16: <alloc::boxed::Box<F,A> as core::ops::function::FnOnce<Args>>::call_once
             at /rustc/2fd73fabe469357a12c2c974c140f67e7cdd76d0/library/alloc/src/boxed.rs:1521:9
      <alloc::boxed::Box<F,A> as core::ops::function::FnOnce<Args>>::call_once
             at /rustc/2fd73fabe469357a12c2c974c140f67e7cdd76d0/library/alloc/src/boxed.rs:1521:9
      std::sys::unix::thread::Thread::new::thread_start
             at /rustc/2fd73fabe469357a12c2c974c140f67e7cdd76d0/library/std/src/sys/unix/thread.rs:71:17
  17: start_thread
  18: __clone


Thread 'Worker devp2p1' panicked at 'db get failed, key: [0, 220, 70, 75, 237, 166, 36, 75, 43, 197, 31, 217, 109, 148, 210, 140, 58, 254, 22, 150, 3, 205, 47, 18, 18, 173, 254, 23, 240, 195, 144, 208, 218], err: Custom { kind: Other, error: "IO error: While open a file for random read: /data/blockchain/eth-data/chains/ethereum/db/906a34e69aec8c0d/overlayrecent/db/383612.sst: No such file or directory" }', /data/blockchain/openethereum/crates/db/db/src/db.rs:307

This is a bug. Please report it at:

    https://github.com/openethereum/openethereum/issues/new


2021-09-22 02:32:26 UTC Finishing work, please wait...
2021-09-22 02:32:26 UTC Panic occured, see stderr for details


====================

   0: panic_hook::set_with::{{closure}}
   1: std::panicking::rust_panic_with_hook
             at /rustc/2fd73fabe469357a12c2c974c140f67e7cdd76d0/library/std/src/panicking.rs:595:17
   2: std::panicking::begin_panic_handler::{{closure}}
             at /rustc/2fd73fabe469357a12c2c974c140f67e7cdd76d0/library/std/src/panicking.rs:497:13
   3: std::sys_common::backtrace::__rust_end_short_backtrace
             at /rustc/2fd73fabe469357a12c2c974c140f67e7cdd76d0/library/std/src/sys_common/backtrace.rs:141:18
   4: rust_begin_unwind
             at /rustc/2fd73fabe469357a12c2c974c140f67e7cdd76d0/library/std/src/panicking.rs:493:5
   5: core::panicking::panic_fmt
             at /rustc/2fd73fabe469357a12c2c974c140f67e7cdd76d0/library/core/src/panicking.rs:92:14
   6: core::option::expect_none_failed
             at /rustc/2fd73fabe469357a12c2c974c140f67e7cdd76d0/library/core/src/option.rs:1300:5
   7: <journaldb::overlayrecentdb::OverlayRecentDB as hash_db::HashDB<keccak_hasher::KeccakHasher,elastic_array::ElasticArray128<u8>>>::get
   8: <&mut dyn hash_db::HashDB<H,T> as hash_db::HashDBRef<H,T>>::get
   9: trie_db::lookup::Lookup<H,C,Q>::look_up
  10: ethcore::state::State<B>::code
  11: ethcore::executive::Executive<B>::transact
  12: ethcore::block::OpenBlock::push_transaction
  13: ethcore::client::client::Importer::import_verified_blocks
  14: <ethcore_service::service::ClientIoHandler as ethcore_io::IoHandler<ethcore::client::io_message::ClientIoMessage>>::message
  15: ethcore_io::worker::Worker::new::{{closure}}::{{closure}}
  16: <futures::future::loop_fn::LoopFn<A,F> as futures::future::Future>::poll
  17: std::sys_common::backtrace::__rust_begin_short_backtrace
  18: core::ops::function::FnOnce::call_once{{vtable.shim}}
  19: <alloc::boxed::Box<F,A> as core::ops::function::FnOnce<Args>>::call_once
             at /rustc/2fd73fabe469357a12c2c974c140f67e7cdd76d0/library/alloc/src/boxed.rs:1521:9
      <alloc::boxed::Box<F,A> as core::ops::function::FnOnce<Args>>::call_once
             at /rustc/2fd73fabe469357a12c2c974c140f67e7cdd76d0/library/alloc/src/boxed.rs:1521:9
      std::sys::unix::thread::Thread::new::thread_start
             at /rustc/2fd73fabe469357a12c2c974c140f67e7cdd76d0/library/std/src/sys/unix/thread.rs:71:17
  20: start_thread
  21: __clone


Thread 'Worker Client0' panicked at 'Low-level database error. Some issue with your hard disk?: Custom { kind: Other, error: "IO error: While open a file for random read: /data/blockchain/eth-data/chains/ethereum/db/906a34e69aec8c0d/overlayrecent/db/361733.sst: No such file or directory" }', crates/db/journaldb/src/overlayrecentdb.rs:180

This is a bug. Please report it at:

    https://github.com/openethereum/openethereum/issues/new


2021-09-22 02:32:26 UTC Panic occured, see stderr for details


====================

   0: panic_hook::set_with::{{closure}}
   1: std::panicking::rust_panic_with_hook
             at /rustc/2fd73fabe469357a12c2c974c140f67e7cdd76d0/library/std/src/panicking.rs:595:17
   2: std::panicking::begin_panic_handler::{{closure}}
             at /rustc/2fd73fabe469357a12c2c974c140f67e7cdd76d0/library/std/src/panicking.rs:497:13
   3: std::sys_common::backtrace::__rust_end_short_backtrace
             at /rustc/2fd73fabe469357a12c2c974c140f67e7cdd76d0/library/std/src/sys_common/backtrace.rs:141:18
   4: rust_begin_unwind
             at /rustc/2fd73fabe469357a12c2c974c140f67e7cdd76d0/library/std/src/panicking.rs:493:5
   5: core::panicking::panic_fmt
             at /rustc/2fd73fabe469357a12c2c974c140f67e7cdd76d0/library/core/src/panicking.rs:92:14
   6: core::option::expect_none_failed
             at /rustc/2fd73fabe469357a12c2c974c140f67e7cdd76d0/library/core/src/option.rs:1300:5
   7: std::sys_common::backtrace::__rust_begin_short_backtrace
   8: core::ops::function::FnOnce::call_once{{vtable.shim}}
   9: <alloc::boxed::Box<F,A> as core::ops::function::FnOnce<Args>>::call_once
             at /rustc/2fd73fabe469357a12c2c974c140f67e7cdd76d0/library/alloc/src/boxed.rs:1521:9
      <alloc::boxed::Box<F,A> as core::ops::function::FnOnce<Args>>::call_once
             at /rustc/2fd73fabe469357a12c2c974c140f67e7cdd76d0/library/alloc/src/boxed.rs:1521:9
      std::sys::unix::thread::Thread::new::thread_start
             at /rustc/2fd73fabe469357a12c2c974c140f67e7cdd76d0/library/std/src/sys/unix/thread.rs:71:17
  10: start_thread
  11: __clone


Thread 'ancient_block_exec' panicked at 'DB flush failed.: Custom { kind: Other, error: "IO error: While open a file for random read: /data/blockchain/eth-data/chains/ethereum/db/906a34e69aec8c0d/overlayrecent/db/400245.sst: No such file or directory" }', crates/ethcore/src/client/client.rs:581

This is a bug. Please report it at:

    https://github.com/openethereum/openethereum/issues/new


2021-09-22 02:32:26 UTC Panic occured, see stderr for details


====================

   0: panic_hook::set_with::{{closure}}
   1: std::panicking::rust_panic_with_hook
             at /rustc/2fd73fabe469357a12c2c974c140f67e7cdd76d0/library/std/src/panicking.rs:595:17
   2: std::panicking::begin_panic_handler::{{closure}}
             at /rustc/2fd73fabe469357a12c2c974c140f67e7cdd76d0/library/std/src/panicking.rs:497:13
   3: std::sys_common::backtrace::__rust_end_short_backtrace
             at /rustc/2fd73fabe469357a12c2c974c140f67e7cdd76d0/library/std/src/sys_common/backtrace.rs:141:18
   4: rust_begin_unwind
             at /rustc/2fd73fabe469357a12c2c974c140f67e7cdd76d0/library/std/src/panicking.rs:493:5
   5: core::panicking::panic_fmt
             at /rustc/2fd73fabe469357a12c2c974c140f67e7cdd76d0/library/core/src/panicking.rs:92:14
   6: core::option::expect_none_failed
             at /rustc/2fd73fabe469357a12c2c974c140f67e7cdd76d0/library/core/src/option.rs:1300:5
   7: ethcore::client::client::Client::shutdown
   8: openethereum::main
   9: std::sys_common::backtrace::__rust_begin_short_backtrace
  10: main
  11: __libc_start_main
  12: _start


Thread 'main' panicked at 'Join handle should not panic: Any', /home/longz/.cargo/git/checkouts/reth-1e6c266c722f7d6d/573e128/crates/util/src/queue/execution_queue.rs:59

This is a bug. Please report it at:

    https://github.com/openethereum/openethereum/issues/new


2021-09-22 02:32:26 UTC Panic occured, see stderr for details


====================

   0: panic_hook::set_with::{{closure}}
   1: std::panicking::rust_panic_with_hook
             at /rustc/2fd73fabe469357a12c2c974c140f67e7cdd76d0/library/std/src/panicking.rs:595:17
   2: std::panicking::begin_panic_handler::{{closure}}
             at /rustc/2fd73fabe469357a12c2c974c140f67e7cdd76d0/library/std/src/panicking.rs:497:13
   3: std::sys_common::backtrace::__rust_end_short_backtrace
             at /rustc/2fd73fabe469357a12c2c974c140f67e7cdd76d0/library/std/src/sys_common/backtrace.rs:141:18
   4: rust_begin_unwind
             at /rustc/2fd73fabe469357a12c2c974c140f67e7cdd76d0/library/std/src/panicking.rs:493:5
   5: core::panicking::panic_fmt
             at /rustc/2fd73fabe469357a12c2c974c140f67e7cdd76d0/library/core/src/panicking.rs:92:14
   6: core::option::expect_none_failed
             at /rustc/2fd73fabe469357a12c2c974c140f67e7cdd76d0/library/core/src/option.rs:1300:5
   7: <journaldb::overlayrecentdb::OverlayRecentDB as hash_db::HashDB<keccak_hasher::KeccakHasher,elastic_array::ElasticArray128<u8>>>::get
   8: <&mut dyn hash_db::HashDB<H,T> as hash_db::HashDBRef<H,T>>::get
   9: trie_db::lookup::Lookup<H,C,Q>::look_up
  10: ethcore::state::State<B>::nonce
  11: ethcore::client::traits::Nonce::latest_nonce
  12: <ethcore::miner::pool_client::CachedNonceClient<C> as ethcore_miner::pool::client::NonceClient>::account_nonce
  13: <(A,B) as txpool::ready::Ready<T>>::is_ready
  14: <txpool::pool::PendingIterator<T,R,S,L> as core::iter::traits::iterator::Iterator>::next
  15: <alloc::vec::Vec<T> as alloc::vec::spec_from_iter::SpecFromIter<T,I>>::from_iter
  16: <ethcore::miner::miner::Miner as ethcore::miner::MinerService>::ready_transactions_filtered::{{closure}}
  17: <ethcore::client::client::Client as ethcore::client::traits::BlockChainClient>::transactions_to_propagate
  18: <ethcore_sync::api::SyncProtocolHandler as ethcore_network::NetworkProtocolHandler>::timeout
  19: <ethcore_network_devp2p::host::Host as ethcore_io::IoHandler<ethcore_network::NetworkIoMessage>>::timeout
  20: ethcore_io::worker::Worker::new::{{closure}}::{{closure}}
  21: <futures::future::loop_fn::LoopFn<A,F> as futures::future::Future>::poll
  22: std::sys_common::backtrace::__rust_begin_short_backtrace
  23: core::ops::function::FnOnce::call_once{{vtable.shim}}
  24: <alloc::boxed::Box<F,A> as core::ops::function::FnOnce<Args>>::call_once
             at /rustc/2fd73fabe469357a12c2c974c140f67e7cdd76d0/library/alloc/src/boxed.rs:1521:9
      <alloc::boxed::Box<F,A> as core::ops::function::FnOnce<Args>>::call_once
             at /rustc/2fd73fabe469357a12c2c974c140f67e7cdd76d0/library/alloc/src/boxed.rs:1521:9
      std::sys::unix::thread::Thread::new::thread_start
             at /rustc/2fd73fabe469357a12c2c974c140f67e7cdd76d0/library/std/src/sys/unix/thread.rs:71:17
  25: start_thread
  26: __clone


Thread 'Worker devp2p2' panicked at 'Low-level database error. Some issue with your hard disk?: Custom { kind: Other, error: "IO error: While open a file for random read: /data/blockchain/eth-data/chains/ethereum/db/906a34e69aec8c0d/overlayrecent/db/294685.sst: No such file or directory" }', crates/db/journaldb/src/overlayrecentdb.rs:180

This is a bug. Please report it at:

    https://github.com/openethereum/openethereum/issues/new