2021-05-16 21:56:09 UTC  36/50 peers      6 MiB chain  0 bytes queue  RPC:  0 conn,    0 req/s,    0 µs
2021-05-16 21:56:11 UTC Imported #12448043 0x8b97…e0b3 (209 txs, 14.75 Mgas, 6331 ms, 60.02 KiB)
2021-05-16 21:56:39 UTC  36/50 peers      6 MiB chain  0 bytes queue  RPC:  0 conn,    0 req/s,    0 µs
2021-05-16 21:57:07 UTC Imported #12448044 0x7cf4…af1d (357 txs, 14.95 Mgas, 5221 ms, 60.37 KiB)
2021-05-16 21:57:10 UTC  36/50 peers      6 MiB chain  0 bytes queue  RPC:  0 conn,    0 req/s,    0 µs
2021-05-16 21:57:44 UTC  36/50 peers      6 MiB chain  0 bytes queue  RPC:  0 conn,    0 req/s,    0 µs
2021-05-16 21:57:48 UTC Imported #12448045 0xac8f…f5e2 (348 txs, 14.96 Mgas, 4977 ms, 59.88 KiB)
2021-05-16 21:58:02 UTC Imported #12448046 0xabee…8d1d (188 txs, 14.95 Mgas, 5593 ms, 58.15 KiB)
2021-05-16 21:58:14 UTC  36/50 peers      6 MiB chain  0 bytes queue  RPC:  0 conn,    0 req/s,    0 µs
2021-05-16 21:58:16 UTC Imported #12448048 0xf0c3…0c58 (170 txs, 14.34 Mgas, 4523 ms, 48.66 KiB)
2021-05-16 21:58:28 UTC Panic occured, see stderr for details


====================

stack backtrace:
   0: panic_hook::set_with::{{closure}}
   1: std::panicking::rust_panic_with_hook
             at /rustc/2fd73fabe469357a12c2c974c140f67e7cdd76d0//library/std/src/panicking.rs:595
   2: std::panicking::begin_panic_handler::{{closure}}
             at /rustc/2fd73fabe469357a12c2c974c140f67e7cdd76d0//library/std/src/panicking.rs:497
   3: std::sys_common::backtrace::__rust_end_short_backtrace
             at /rustc/2fd73fabe469357a12c2c974c140f67e7cdd76d0//library/std/src/sys_common/backtrace.rs:141
   4: rust_begin_unwind
             at /rustc/2fd73fabe469357a12c2c974c140f67e7cdd76d0//library/std/src/panicking.rs:493
   5: core::panicking::panic_fmt
             at /rustc/2fd73fabe469357a12c2c974c140f67e7cdd76d0//library/core/src/panicking.rs:92
   6: core::option::expect_none_failed
             at /rustc/2fd73fabe469357a12c2c974c140f67e7cdd76d0//library/core/src/option.rs:1300
   7: <ethcore_network_devp2p::host::Host as ethcore_io::IoHandler<ethcore_network::NetworkIoMessage>>::update_stream
   8: mio::deprecated::event_loop::EventLoop<H>::run
   9: std::sys_common::backtrace::__rust_begin_short_backtrace
  10: core::ops::function::FnOnce::call_once{{vtable.shim}}
  11: <alloc::boxed::Box<F,A> as core::ops::function::FnOnce<Args>>::call_once
             at /rustc/2fd73fabe469357a12c2c974c140f67e7cdd76d0/library/alloc/src/boxed.rs:1521
      <alloc::boxed::Box<F,A> as core::ops::function::FnOnce<Args>>::call_once
             at /rustc/2fd73fabe469357a12c2c974c140f67e7cdd76d0/library/alloc/src/boxed.rs:1521
      std::sys::unix::thread::Thread::new::thread_start
             at /rustc/2fd73fabe469357a12c2c974c140f67e7cdd76d0//library/std/src/sys/unix/thread.rs:71
  12: start_thread
  13: __clone


Thread '<unnamed>' panicked at 'Error reregistering UDP socket: Os { code: 9, kind: Other, message: "Bad file descriptor" }', crates/net/network-devp2p/src/host.rs:1425

This is a bug. Please report it at:

    https://github.com/openethereum/openethereum/issues/new


2021-05-16 21:58:28 UTC Finishing work, please wait...
2021-05-16 21:58:28 UTC Error on IO service shutdown: NotifyError::Closed(..)
Error: 1